Workbook

Sheet README
A1: Llama 3.1 70B inference sweep: parameter workbook
A3: What this is | B3: All parameters measured in the 150-point sweep (5 input lengths x 6 output lengths x 5 request rates, 100 requests each) plus the derived quantities discussed in the report.
A4: Sheets | B4: Data: one row per load point (measured columns, gray headers; formula columns, green headers). Assumptions: model and hardware constants (blue = editable). KV_Capacity: KV cache per sequence and sequences that fit. By_Output_Len / By_Input_Len / By_Rate: averages. Rate_Effect: full output-length x request-rate grids (TTFT, tokens per joule, TPOT, power, SM active) behind Section 3. Maximum Throughput: compute-ceiling and PCIe-ceiling estimates.
A5: Colour code | B5: Blue text = hardcoded input. Black text = formula or measured data. Yellow fill = a key input to change. Change inputs on Assumptions and everything recalculates.
A6: Setup | B6: 4x RTX PRO 6000 Blackwell (PCIe, no NVLink), vLLM, tensor-parallel size 4, FP8 weights, BF16 KV cache, --gpu-memory-utilization 0.88, --max-model-len 16384.
A7: Units | B7: PCIe TX/RX: DCGM reports bytes per second per GPU (columns ending _Bps); the Data sheet also gives GB/s. Power in watts per GPU. VRAM in MiB per GPU. KV-cache columns are percent of the pre-allocated pool, from vLLM server logs.
A8: Averages | B8: DCGM averages are time-averages over each run window across all 4 GPUs, using numeric samples only (leading N/A samples excluded; idle samples at the start and end are included).
A9: tensor_active | B9: A duty cycle: the share of sampled time the tensor pipes were busy, averaged over SMs and GPUs. It is not a share of peak FLOPs.
A10: Arrival window | B10: elapsed_s includes the time to submit the requests (num_prompts / rate). remainder_s subtracts it. Compare remainder_s, not elapsed_s, when judging the effect of request rate.
A11: FLOPs per token | B11: 2 x parameters (Assumptions!B16). It ignores attention FLOPs, so achieved TFLOPS is slightly understated at long contexts.
A12: Estimates | B12: Dense FP8 peak (1,000 TFLOPS per GPU) is an estimate. The PCIe link capability (5.0 x16, 63 GB/s per direction) was confirmed with nvidia-smi; achievable bandwidth is typically 80 to 85% of it. Both are labelled on Assumptions. Percentages built on them inherit that uncertainty.
A13: Not included | B13: The manifest columns peak_sm_active, peak_tensor_active and peak_dram_active (mislabeled in older manifests; use the dcgm_* columns here) and peak_output_throughput (not captured by the analysis script).
A14: Measurement window | B14: elapsed_s and the DCGM/nvidia-smi averages cover the whole vllm bench command, including several seconds of tool start-up and teardown around the requests. For the shortest runs (13-30 s) idle samples are a large share of the window and lower the averages; for runs longer than about two minutes the effect is negligible.
... A16: Source data | B16: full_summary.csv produced by analyze_sweep.py from manifest.csv, the bench_*.json files, the raw dcgm_*.log files, and the vLLM server logs.

Sheet Assumptions
A1: Assumptions and derived constants
A2: Blue cells are hardcoded inputs (edit these). Black cells are formulas. Every other sheet reads from here.
A3: Parameter | B3: Value | C3: Unit | D3: Type | E3: Source / note
A4: Model parameters | B4: 70000000000 | C4: parameters | D4: Input | E4: Llama 3.1 70B, ~70 billion parameters (approximate; actual is about 70.6B).
A5: Transformer layers | B5: 80 | C5: layers | D5: Input | E5: Llama 3.1 70B architecture (config.json num_hidden_layers). Verify in the checkpoint folder.
A6: KV heads (GQA) | B6: 8 | C6: heads | D6: Input | E6: Llama 3.1 70B config.json num_key_value_heads. Verify in the checkpoint folder.
A7: Head dimension | B7: 128 | C7: elements | D7: Input | E7: Llama 3.1 70B: hidden size 8192 / 64 attention heads. Verify in config.json.
A8: Bytes per KV-cache element | B8: 2 | C8: bytes | D8: Input | E8: BF16. No --kv-cache-dtype flag was used, so vLLM kept the model compute dtype for the cache.
A9: Tensor-parallel size (GPUs) | B9: 4 | C9: GPUs | D9: Input | E9: --tensor-parallel-size 4 in the vllm serve command.
A10: Model weights per GPU | B10: 16.98 | C10: GiB | D10: Input | E10: From the vLLM startup log: 'Model loading took 16.98 GiB memory'.
A11: Peak dense FP8 per GPU (estimate) | B11: 1000 | C11: TFLOPS | D11: Estimate | E11: NVIDIA publishes 2,000 TFLOPS for FP8 with 2:4 sparsity only. Dense is taken as half. This is an estimate, not a vendor figure.
A12: Memory bandwidth per GPU | B12: 1.6 | C12: TB/s | D12: Input | E12: Published GDDR7 bandwidth for the RTX PRO 6000 Blackwell.
A13: PCIe link, theoretical per direction | B13: 63 | C13: GB/s | D13: Assumption | E13: PCIe 5.0 x16 per GPU, confirmed with nvidia-smi (max generation 5, width 16 on all 8 GPUs). 63 GB/s is the theoretical peak per direction; achievable throughput is typically 80 to 85% of it.
A15: Derived constants (formulas)
A16: FLOPs per generated token | B16: =2*B4 -> 140000000000 | C16: FLOP | D16: Formula | E16: 2 x parameters (forward pass only). Ignores attention FLOPs, which grow with context length.
A17: KV cache bytes per token, all GPUs | B17: =2*B5*B6*B7*B8 -> 327680 | C17: bytes | D17: Formula | E17: 2 (K and V) x layers x KV heads x head dim x bytes per element.
A18: KV cache bytes per token, per GPU | B18: =B17/B9 -> 81920 | C18: bytes | D18: Formula | E18: KV heads are split across the tensor-parallel GPUs.
A19: KV cache per token, per GPU | B19: =B18/1024 -> 80 | C19: KiB | D19: Formula
A20: Reserved VRAM per GPU, measured average | B20: =AVERAGE(Data!$M$2:$M$151)/1024 -> 85.17607 | C20: GiB | D20: Formula | E20: Average of avg_mem_mib across all load points, converted from MiB.
A21: KV pool upper bound per GPU | B21: =B20-B10 -> 68.19607 | C21: GiB | D21: Formula | E21: Reserved VRAM minus weights. Upper bound: CUDA graphs and activation buffers take some of it.
A22: Weight-read time per decode step, per GPU | B22: =B10*2^30/(B12*1000000000000)*1000 -> 11.395085 | C22: ms | D22: Formula | E22: Bandwidth-bound floor: each decode step streams all weights from memory once.
A23: Compute time per token, per GPU, at est. peak | B23: =B16/B9/(B11*1000000000000)*1000000 -> 35 | C23: microseconds | D23: Formula | E23: FLOPs per token divided across the GPUs at the estimated dense FP8 peak.
A24: Ridge-point batch size | B24: =B22*1000/B23 -> 325.57386 | C24: sequences | D24: Formula | E24: Concurrent sequences at which compute time per step equals weight-read time (at 100% of est. peak).

Sheet Data
A1: input_len | B1: output_len | C1: rate_rps | D1: num_prompts | E1: elapsed_s | F1: mean_ttft_ms | G1: mean_tpot_ms | H1: output_throughput_tok_s | I1: avg_gpu_util_pct | J1: peak_gpu_util_pct | K1: avg_power_w | L1: peak_power_w | M1: avg_mem_mib | N1: peak_mem_mib | O1: avg_kv_cache_pct | P1: peak_kv_cache_pct | Q1: dcgm_avg_GRACT | R1: dcgm_peak_GRACT | S1: dcgm_avg_SMACT | T1: dcgm_peak_SMACT | U1: dcgm_avg_SMOCC | V1: dcgm_peak_SMOCC | W1: dcgm_avg_TENSO | X1: dcgm_peak_TENSO | Y1: dcgm_avg_DRAMA | Z1: dcgm_peak_DRAMA | AA1: dcgm_avg_PCITX_Bps | AB1: dcgm_peak_PCITX_Bps | AC1: dcgm_avg_PCIRX_Bps | AD1: dcgm_peak_PCIRX_Bps | AE1: context_tokens | AF1: submission_window_s | AG1: remainder_s | AH1: achieved_rps | AI1: pcie_tx_avg_GBps | AJ1: pcie_tx_peak_GBps | AK1: pcie_rx_avg_GBps | AL1: pcie_rx_peak_GBps | AM1: pcie_tx_avg_pct_of_link | AN1: pcie_rx_avg_pct_of_link | AO1: pcie_tx_MB_per_token | AP1: achieved_TFLOPS_total | AQ1: achieved_TFLOPS_per_GPU | AR1: pct_of_est_dense_FP8_peak | AS1: concurrent_seqs_littles_law | AT1: kv_gib_avg_per_gpu | AU1: kv_gib_peak_per_gpu | AV1: tokens_per_joule | AW1: occupancy_when_active
A2: 128 | B2: 128 | C2: 5 | D2: 100 | E2: 31 | F2: 96.453046 | G2: 28.784748 | H2: 531.19701 | I2: 79.2 | J2: 99 | K2: 220.9 | L2: 282.4 | M2: 86932.5 | N2: 86933 | O2: 0.55 | P2: 0.6 | Q2: 0.80375 | R2: 0.992 | S2: 0.35073333 | T2: 0.487 | U2: 0.03365 | V2: 0.048 | W2: 0.08015 | X2: 0.112 | Y2: 0.33211667 | Z2: 0.492 | AA2: 7.2590929e+09 | AB2: 12030579841 | AC2: 6.4554706e+09 | AD2: 10634238760 | AE2: =A2+B2 -> 256 | AF2: =D2/C2 -> 20 | AG2: =E2-AF2 -> 11 | AH2: =D2/E2 -> 3.2258065 | AI2: =AA2/1000000000 -> 7.2590929 | AJ2: =AB2/1000000000 -> 12.03058 | AK2: =AC2/1000000000 -> 6.4554706 | AL2: =AD2/1000000000 -> 10.634239 | AM2: =AI2/Assumptions!$B$13 -> 0.1152237 | AN2: =AK2/Assumptions!$B$13 -> 0.10246779 | AO2: =AA2/H2/1000000 -> 13.665538 | AP2: =H2*Assumptions!$B$16/1000000000000 -> 74.367582 | AQ2: =AP2/Assumptions!$B$9 -> 18.591896 | AR2: =AQ2/Assumptions!$B$11 -> 0.018591896 | AS2: =H2*G2/1000 -> 15.290372 | AT2: =Assumptions!$B$21*O2/100 -> 0.37507838 | AU2: =Assumptions!$B$21*P2/100 -> 0.40917642 | AV2: =H2/(K2*Assumptions!$B$9) -> 0.60117362 | AW2: =U2/S2 -> 0.095941836
A3: 128 | B3: 128 | C3: 10 | D3: 100 | E3: 21 | F3: 86.252236 | G3: 33.081641 | H3: 880.39514 | I3: 71 | J3: 100 | K3: 194.8 | L3: 275 | M3: 86933 | N3: 86933 | O3: 0.6 | P3: 1.2 | Q3: 0.7369 | R3: 0.993 | S3: 0.284525 | T3: 0.506 | U3: 0.024925 | V3: 0.049 | W3: 0.060075 | X3: 0.088 | Y3: 0.280075 | Z3: 0.496 | AA3: 7.5830927e+09 | AB3: 13627019743 | AC3: 6.7541512e+09 | AD3: 12239289773 | AE3: =A3+B3 -> 256 | AF3: =D3/C3 -> 10 | AG3: =E3-AF3 -> 11 | AH3: =D3/E3 -> 4.7619048 | AI3: =AA3/1000000000 -> 7.5830927 | AJ3: =AB3/1000000000 -> 13.62702 | AK3: =AC3/1000000000 -> 6.7541512 | AL3: =AD3/1000000000 -> 12.23929 | AM3: =AI3/Assumptions!$B$13 -> 0.12036655 | AN3: =AK3/Assumptions!$B$13 -> 0.10720875 | AO3: =AA3/H3/1000000 -> 8.6132832 | AP3: =H3*Assumptions!$B$16/1000000000000 -> 123.25532 | AQ3: =AP3/Assumptions!$B$9 -> 30.81383 | AR3: =AQ3/Assumptions!$B$11 -> 0.03081383 | AS3: =H3*G3/1000 -> 29.124916 | AT3: =Assumptions!$B$21*O3/100 -> 0.40917642 | AU3: =Assumptions!$B$21*P3/100 -> 0.81835284 | AV3: =H3/(K3*Assumptions!$B$9) -> 1.1298706 | AW3: =U3/S3 -> 0.087602144
A4: 128 | B4: 128 | C4: 20 | D4: 100 | E4: 17 | F4: 89.885705 | G4: 35.893086 | H4: 1268.9143 | I4: 61.8 | J4: 100 | K4: 184.6 | L4: 302 | M4: 86980.2 | N4: 87089 | O4: 0.75 | P4: 1.5 | Q4: 0.66528125 | R4: 0.994 | S4: 0.23596875 | T4: 0.409 | U4: 0.020387097 | V4: 0.04 | W4: 0.069870968 | X4: 0.152 | Y4: 0.245 | Z4: 0.397 | AA4: 6.6660843e+09 | AB4: 13251188765 | AC4: 5.8997869e+09 | AD4: 11865231496 | AE4: =A4+B4 -> 256 | AF4: =D4/C4 -> 5 | AG4: =E4-AF4 -> 12 | AH4: =D4/E4 -> 5.8823529 | AI4: =AA4/1000000000 -> 6.6660843 | AJ4: =AB4/1000000000 -> 13.251189 | AK4: =AC4/1000000000 -> 5.8997869 | AL4: =AD4/1000000000 -> 11.865231 | AM4: =AI4/Assumptions!$B$13 -> 0.10581086 | AN4: =AK4/Assumptions!$B$13 -> 0.093647411 | AO4: =AA4/H4/1000000 -> 5.2533762 | AP4: =H4*Assumptions!$B$16/1000000000000 -> 177.64801 | AQ4: =AP4/Assumptions!$B$9 -> 44.412002 | AR4: =AQ4/Assumptions!$B$11 -> 0.044412002 | AS4: =H4*G4/1000 -> 45.545252 | AT4: =Assumptions!$B$21*O4/100 -> 0.51147052 | AU4: =Assumptions!$B$21*P4/100 -> 1.022941 | AV4: =H4/(K4*Assumptions!$B$9) -> 1.7184647 | AW4: =U4/S4 -> 0.086397444
A5: 128 | B5: 128 | C5: 50 | D5: 100 | E5: 14 | F5: 96.044608 | G5: 38.969094 | H5: 1653.4021 | I5: 56.8 | J5: 100 | K5: 171.2 | L5: 289 | M5: 87131 | N5: 87187 | O5: 2.1 | P5: 2.1 | Q5: 0.57920833 | R5: 0.995 | S5: 0.17129167 | T5: 0.348 | U5: 0.014208333 | V5: 0.028 | W5: 0.068375 | X5: 0.139 | Y5: 0.17345833 | Z5: 0.338 | AA5: 6.7275805e+09 | AB5: 13332094679 | AC5: 5.911064e+09 | AD5: 11670771344 | AE5: =A5+B5 -> 256 | AF5: =D5/C5 -> 2 | AG5: =E5-AF5 -> 12 | AH5: =D5/E5 -> 7.1428571 | AI5: =AA5/1000000000 -> 6.7275805 | AJ5: =AB5/1000000000 -> 13.332095 | AK5: =AC5/1000000000 -> 5.911064 | AL5: =AD5/1000000000 -> 11.670771 | AM5: =AI5/Assumptions!$B$13 -> 0.10678699 | AN5: =AK5/Assumptions!$B$13 -> 0.093826413 | AO5: =AA5/H5/1000000 -> 4.068932 | AP5: =H5*Assumptions!$B$16/1000000000000 -> 231.47629 | AQ5: =AP5/Assumptions!$B$9 -> 57.869072 | AR5: =AQ5/Assumptions!$B$11 -> 0.057869072 | AS5: =H5*G5/1000 -> 64.43158 | AT5: =Assumptions!$B$21*O5/100 -> 1.4321175 | AU5: =Assumptions!$B$21*P5/100 -> 1.4321175 | AV5: =H5/(K5*Assumptions!$B$9) -> 2.4144306 | AW5: =U5/S5 -> 0.082948188
A6: 128 | B6: 128 | C6: 100 | D6: 100 | E6: 13 | F6: 99.149739 | G6: 39.67563 | H6: 1832.8174 | I6: 56.8 | J6: 100 | K6: 167.4 | L6: 274.7 | M6: 87187 | N6: 87187 | O6: 2.5 | P6: 2.5 | Q6: 0.57925 | R6: 0.995 | S6: 0.168 | T6: 0.371 | U6: 0.014956522 | V6: 0.032 | W6: 0.070130435 | X6: 0.141 | Y6: 0.186 | Z6: 0.364 | AA6: 6.8177138e+09 | AB6: 13331502391 | AC6: 5.9866119e+09 | AD6: 11670868931 | AE6: =A6+B6 -> 256 | AF6: =D6/C6 -> 1 | AG6: =E6-AF6 -> 12 | AH6: =D6/E6 -> 7.6923077 | AI6: =AA6/1000000000 -> 6.8177138 | AJ6: =AB6/1000000000 -> 13.331502 | AK6: =AC6/1000000000 -> 5.9866119 | AL6: =AD6/1000000000 -> 11.670869 | AM6: =AI6/Assumptions!$B$13 -> 0.10821768 | AN6: =AK6/Assumptions!$B$13 -> 0.095025586 | AO6: =AA6/H6/1000000 -> 3.7197998 | AP6: =H6*Assumptions!$B$16/1000000000000 -> 256.59444 | AQ6: =AP6/Assumptions!$B$9 -> 64.14861 | AR6: =AQ6/Assumptions!$B$11 -> 0.06414861 | AS6: =H6*G6/1000 -> 72.718185 | AT6: =Assumptions!$B$21*O6/100 -> 1.7049017 | AU6: =Assumptions!$B$21*P6/100 -> 1.7049017 | AV6: =H6/(K6*Assumptions!$B$9) -> 2.7371825 | AW6: =U6/S6 -> 0.089026915
A7: 128 | B7: 512 | C7: 5 | D7: 100 | E7: 46 | F7: 89.879354 | G7: 35.907159 | H7: 1267.073 | I7: 86.4 | J7: 100 | K7: 240.3 | L7: 315 | M7: 87187 | N7: 87187 | O7: 1.72 | P7: 3.3 | Q7: 0.87814773 | R7: 0.996 | S7: 0.33576136 | T7: 0.543 | U7: 0.028409091 | V7: 0.053 | W7: 0.093034091 | X7: 0.165 | Y7: 0.32811364 | Z7: 0.541 | AA7: 9.4653555e+09 | AB7: 14297010609 | AC7: 8.3766683e+09 | AD7: 12832353150 | AE7: =A7+B7 -> 640 | AF7: =D7/C7 -> 20 | AG7: =E7-AF7 -> 26 | AH7: =D7/E7 -> 2.173913 | AI7: =AA7/1000000000 -> 9.4653555 | AJ7: =AB7/1000000000 -> 14.297011 | AK7: =AC7/1000000000 -> 8.3766683 | AL7: =AD7/1000000000 -> 12.832353 | AM7: =AI7/Assumptions!$B$13 -> 0.15024374 | AN7: =AK7/Assumptions!$B$13 -> 0.13296299 | AO7: =AA7/H7/1000000 -> 7.4702529 | AP7: =H7*Assumptions!$B$16/1000000000000 -> 177.39022 | AQ7: =AP7/Assumptions!$B$9 -> 44.347554 | AR7: =AQ7/Assumptions!$B$11 -> 0.044347554 | AS7: =H7*G7/1000 -> 45.496991 | AT7: =Assumptions!$B$21*O7/100 -> 1.1729724 | AU7: =Assumptions!$B$21*P7/100 -> 2.2504703 | AV7: =H7/(K7*Assumptions!$B$9) -> 1.3182199 | AW7: =U7/S7 -> 0.084610959
A8: 128 | B8: 512 | C8: 10 | D8: 100 | E8: 39 | F8: 90.42279 | G8: 38.638226 | H8: 1569.3714 | I8: 83.9 | J8: 100 | K8: 239 | L8: 312.8 | M8: 87187 | N8: 87187 | O8: 2.3 | P8: 4.4 | Q8: 0.84134211 | R8: 1 | S8: 0.30806579 | T8: 0.538 | U8: 0.025671053 | V8: 0.054 | W8: 0.097789474 | X8: 0.166 | Y8: 0.30511842 | Z8: 0.534 | AA8: 9.4436822e+09 | AB8: 13706013424 | AC8: 8.2517894e+09 | AD8: 12150063460 | AE8: =A8+B8 -> 640 | AF8: =D8/C8 -> 10 | AG8: =E8-AF8 -> 29 | AH8: =D8/E8 -> 2.5641026 | AI8: =AA8/1000000000 -> 9.4436822 | AJ8: =AB8/1000000000 -> 13.706013 | AK8: =AC8/1000000000 -> 8.2517894 | AL8: =AD8/1000000000 -> 12.150063 | AM8: =AI8/Assumptions!$B$13 -> 0.14989972 | AN8: =AK8/Assumptions!$B$13 -> 0.13098078 | AO8: =AA8/H8/1000000 -> 6.0174934 | AP8: =H8*Assumptions!$B$16/1000000000000 -> 219.712 | AQ8: =AP8/Assumptions!$B$9 -> 54.928 | AR8: =AQ8/Assumptions!$B$11 -> 0.054928 | AS8: =H8*G8/1000 -> 60.637727 | AT8: =Assumptions!$B$21*O8/100 -> 1.5685096 | AU8: =Assumptions!$B$21*P8/100 -> 3.0006271 | AV8: =H8/(K8*Assumptions!$B$9) -> 1.6416019 | AW8: =U8/S8 -> 0.083329774
A9: 128 | B9: 512 | C9: 20 | D9: 100 | E9: 35 | F9: 90.205228 | G9: 39.86727 | H9: 1774.571 | I9: 82.8 | J9: 100 | K9: 239.1 | L9: 302.2 | M9: 87187 | N9: 87187 | O9: 3.1333333 | P9: 5.5 | Q9: 0.85211765 | R9: 0.996 | S9: 0.29491176 | T9: 0.536 | U9: 0.025058824 | V9: 0.052 | W9: 0.10225 | X9: 0.149 | Y9: 0.2935 | Z9: 0.534 | AA9: 9.656201e+09 | AB9: 13212650465 | AC9: 8.4994483e+09 | AD9: 11660316275 | AE9: =A9+B9 -> 640 | AF9: =D9/C9 -> 5 | AG9: =E9-AF9 -> 30 | AH9: =D9/E9 -> 2.8571429 | AI9: =AA9/1000000000 -> 9.656201 | AJ9: =AB9/1000000000 -> 13.21265 | AK9: =AC9/1000000000 -> 8.4994483 | AL9: =AD9/1000000000 -> 11.660316 | AM9: =AI9/Assumptions!$B$13 -> 0.15327303 | AN9: =AK9/Assumptions!$B$13 -> 0.13491188 | AO9: =AA9/H9/1000000 -> 5.4414283 | AP9: =H9*Assumptions!$B$16/1000000000000 -> 248.43994 | AQ9: =AP9/Assumptions!$B$9 -> 62.109986 | AR9: =AQ9/Assumptions!$B$11 -> 0.062109986 | AS9: =H9*G9/1000 -> 70.747302 | AT9: =Assumptions!$B$21*O9/100 -> 2.1368102 | AU9: =Assumptions!$B$21*P9/100 -> 3.7507838 | AV9: =H9/(K9*Assumptions!$B$9) -> 1.8554695 | AW9: =U9/S9 -> 0.084970579
A10: 128 | B10: 512 | C10: 50 | D10: 100 | E10: 33 | F10: 95.348669 | G10: 40.491962 | H10: 1918.2832 | I10: 81.9 | J10: 100 | K10: 235.9 | L10: 306.2 | M10: 87187 | N10: 87187 | O10: 3.1333333 | P10: 5.1 | Q10: 0.84415625 | R10: 0.996 | S10: 0.27945313 | T10: 0.524 | U10: 0.024079365 | V10: 0.05 | W10: 0.10536508 | X10: 0.159 | Y10: 0.29448387 | Z10: 0.516 | AA10: 9.9045613e+09 | AB10: 13315040015 | AC10: 8.7051318e+09 | AD10: 11655909995 | AE10: =A10+B10 -> 640 | AF10: =D10/C10 -> 2 | AG10: =E10-AF10 -> 31 | AH10: =D10/E10 -> 3.030303 | AI10: =AA10/1000000000 -> 9.9045613 | AJ10: =AB10/1000000000 -> 13.31504 | AK10: =AC10/1000000000 -> 8.7051318 | AL10: =AD10/1000000000 -> 11.65591 | AM10: =AI10/Assumptions!$B$13 -> 0.15721526 | AN10: =AK10/Assumptions!$B$13 -> 0.13817669 | AO10: =AA10/H10/1000000 -> 5.1632426 | AP10: =H10*Assumptions!$B$16/1000000000000 -> 268.55964 | AQ10: =AP10/Assumptions!$B$9 -> 67.13991 | AR10: =AQ10/Assumptions!$B$11 -> 0.06713991 | AS10: =H10*G10/1000 -> 77.675049 | AT10: =Assumptions!$B$21*O10/100 -> 2.1368102 | AU10: =Assumptions!$B$21*P10/100 -> 3.4779996 | AV10: =H10/(K10*Assumptions!$B$9) -> 2.032941 | AW10: =U10/S10 -> 0.086166025
A11: 128 | B11: 512 | C11: 100 | D11: 100 | E11: 32 | F11: 99.906297 | G11: 40.663432 | H11: 1967.2664 | I11: 80.9 | J11: 100 | K11: 234.2 | L11: 300.9 | M11: 87187 | N11: 87187 | O11: 3.4333333 | P11: 5 | Q11: 0.83675 | R11: 0.996 | S11: 0.26245 | T11: 0.436 | U11: 0.022389831 | V11: 0.039 | W11: 0.10627119 | X11: 0.152 | Y11: 0.2795 | Z11: 0.417 | AA11: 1.0312082e+10 | AB11: 13789898033 | AC11: 9.0510946e+09 | AD11: 12258865793 | AE11: =A11+B11 -> 640 | AF11: =D11/C11 -> 1 | AG11: =E11-AF11 -> 31 | AH11: =D11/E11 -> 3.125 | AI11: =AA11/1000000000 -> 10.312082 | AJ11: =AB11/1000000000 -> 13.789898 | AK11: =AC11/1000000000 -> 9.0510946 | AL11: =AD11/1000000000 -> 12.258866 | AM11: =AI11/Assumptions!$B$13 -> 0.16368385 | AN11: =AK11/Assumptions!$B$13 -> 0.14366817 | AO11: =AA11/H11/1000000 -> 5.2418333 | AP11: =H11*Assumptions!$B$16/1000000000000 -> 275.4173 | AQ11: =AP11/Assumptions!$B$9 -> 68.854324 | AR11: =AQ11/Assumptions!$B$11 -> 0.068854324 | AS11: =H11*G11/1000 -> 79.995803 | AT11: =Assumptions!$B$21*O11/100 -> 2.3413984 | AU11: =Assumptions!$B$21*P11/100 -> 3.4098035 | AV11: =H11/(K11*Assumptions!$B$9) -> 2.0999855 | AW11: =U11/S11 -> 0.085310842
A12: 128 | B12: 1024 | C12: 5 | D12: 100 | E12: 72 | F12: 89.802924 | G12: 39.359941 | H12: 1547.8223 | I12: 91.3 | J12: 100 | K12: 250.3 | L12: 313.8 | M12: 87187 | N12: 87187 | O12: 4.075 | P12: 9 | Q12: 0.9183 | R12: 0.996 | S12: 0.34909286 | T12: 0.556 | U12: 0.029378571 | V12: 0.055 | W12: 0.10650714 | X12: 0.165 | Y12: 0.34953571 | Z12: 0.559 | AA12: 1.0199705e+10 | AB12: 15220624577 | AC12: 9.0039859e+09 | AD12: 13667287754 | AE12: =A12+B12 -> 1152 | AF12: =D12/C12 -> 20 | AG12: =E12-AF12 -> 52 | AH12: =D12/E12 -> 1.3888889 | AI12: =AA12/1000000000 -> 10.199705 | AJ12: =AB12/1000000000 -> 15.220625 | AK12: =AC12/1000000000 -> 9.0039859 | AL12: =AD12/1000000000 -> 13.667288 | AM12: =AI12/Assumptions!$B$13 -> 0.16190008 | AN12: =AK12/Assumptions!$B$13 -> 0.14292041 | AO12: =AA12/H12/1000000 -> 6.5897128 | AP12: =H12*Assumptions!$B$16/1000000000000 -> 216.69513 | AQ12: =AP12/Assumptions!$B$9 -> 54.173782 | AR12: =AQ12/Assumptions!$B$11 -> 0.054173782 | AS12: =H12*G12/1000 -> 60.922196 | AT12: =Assumptions!$B$21*O12/100 -> 2.7789898 | AU12: =Assumptions!$B$21*P12/100 -> 6.1376463 | AV12: =H12/(K12*Assumptions!$B$9) -> 1.5459672 | AW12: =U12/S12 -> 0.084156896
A13: 128 | B13: 1024 | C13: 10 | D13: 100 | E13: 64 | F13: 90.277004 | G13: 40.427203 | H13: 1756.0763 | I13: 90.2 | J13: 100 | K13: 245.2 | L13: 305.4 | M13: 87187 | N13: 87187 | O13: 4.6142857 | P13: 9.7 | Q13: 0.91387097 | R13: 0.996 | S13: 0.33254839 | T13: 0.551 | U13: 0.027685484 | V13: 0.053 | W13: 0.1098871 | X13: 0.164 | Y13: 0.33641129 | Z13: 0.548 | AA13: 1.0539533e+10 | AB13: 13595181605 | AC13: 9.2558058e+09 | AD13: 12110481436 | AE13: =A13+B13 -> 1152 | AF13: =D13/C13 -> 10 | AG13: =E13-AF13 -> 54 | AH13: =D13/E13 -> 1.5625 | AI13: =AA13/1000000000 -> 10.539533 | AJ13: =AB13/1000000000 -> 13.595182 | AK13: =AC13/1000000000 -> 9.2558058 | AL13: =AD13/1000000000 -> 12.110481 | AM13: =AI13/Assumptions!$B$13 -> 0.16729417 | AN13: =AK13/Assumptions!$B$13 -> 0.14691755 | AO13: =AA13/H13/1000000 -> 6.0017508 | AP13: =H13*Assumptions!$B$16/1000000000000 -> 245.85068 | AQ13: =AP13/Assumptions!$B$9 -> 61.462671 | AR13: =AQ13/Assumptions!$B$11 -> 0.061462671 | AS13: =H13*G13/1000 -> 70.993253 | AT13: =Assumptions!$B$21*O13/100 -> 3.1467615 | AU13: =Assumptions!$B$21*P13/100 -> 6.6150188 | AV13: =H13/(K13*Assumptions!$B$9) -> 1.790453 | AW13: =U13/S13 -> 0.083252498
... A151: 1024 | B151: 10240 | C151: 100 | D151: 100 | E151: 849 | F151: 2958.8823 | G151: 67.916253 | H151: 1209.4331 | I151: 99 | J151: 100 | K151: 310.2 | L151: 364.9 | M151: 88307 | N151: 88307 | O151: 64.065882 | P151: 99.6 | Q151: 0.99036026 | R151: 1 | S151: 0.564273 | T151: 0.683 | U151: 0.039790684 | V151: 0.072 | W151: 0.1518296 | X151: 0.24 | Y151: 0.56789564 | Z151: 0.693 | AA151: 7.479554e+09 | AB151: 31122928543 | AC151: 6.5585586e+09 | AD151: 27234708697 | AE151: =A151+B151 -> 11264 | AF151: =D151/C151 -> 1 | AG151: =E151-AF151 -> 848 | AH151: =D151/E151 -> 0.11778563 | AI151: =AA151/1000000000 -> 7.479554 | AJ151: =AB151/1000000000 -> 31.122929 | AK151: =AC151/1000000000 -> 6.5585586 | AL151: =AD151/1000000000 -> 27.234709 | AM151: =AI151/Assumptions!$B$13 -> 0.11872308 | AN151: =AK151/Assumptions!$B$13 -> 0.1041041 | AO151: =AA151/H151/1000000 -> 6.1843468 | AP151: =H151*Assumptions!$B$16/1000000000000 -> 169.32064 | AQ151: =AP151/Assumptions!$B$9 -> 42.33016 | AR151: =AQ151/Assumptions!$B$11 -> 0.04233016 | AS151: =H151*G151/1000 -> 82.140167 | AT151: =Assumptions!$B$21*O151/100 -> 43.690414 | AU151: =Assumptions!$B$21*P151/100 -> 67.923285 | AV151: =H151/(K151*Assumptions!$B$9) -> 0.97472045 | AW151: =U151/S151 -> 0.070516726

Sheet By_Output_Len
A1: Averages by output length
A2: Each row averages the 25 load points (5 input lengths x 5 rates) that share that output length. "max" columns take the maximum.
A4: output_len | B4: Output throughput (tok/s) | C4: Mean TTFT (ms) | D4: Mean TPOT (ms) | E4: Elapsed (s) | F4: Elapsed minus arrival window (s) | G4: Avg GPU util (%) | H4: Avg power (W) | I4: GR engine active (avg) | J4: SM active (avg) | K4: SM occupancy (avg) | L4: Tensor active (avg) | M4: Tensor active (max peak) | N4: DRAM active (avg) | O4: PCIe TX avg (GB/s) | P4: PCIe TX peak (GB/s, max) | Q4: PCIe RX avg (GB/s) | R4: PCIe RX peak (GB/s, max) | S4: KV cache in use, avg (%) | T4: KV cache in use, peak (%, max) | U4: PCIe TX per token (MB per GPU) | V4: Achieved TFLOPS per GPU | W4: % of est. dense FP8 peak | X4: Concurrent sequences (Little) | Y4: Tokens per joule
A5: 128 | B5: =AVERAGEIFS(Data!$H$2:$H$151,Data!$B$2:$B$151,$A5) -> 1202.0916 | C5: =AVERAGEIFS(Data!$F$2:$F$151,Data!$B$2:$B$151,$A5) -> 106.34532 | D5: =AVERAGEIFS(Data!$G$2:$G$151,Data!$B$2:$B$151,$A5) -> 37.804395 | E5: =AVERAGEIFS(Data!$E$2:$E$151,Data!$B$2:$B$151,$A5) -> 19.16 | F5: =AVERAGEIFS(Data!$AG$2:$AG$151,Data!$B$2:$B$151,$A5) -> 11.56 | G5: =AVERAGEIFS(Data!$I$2:$I$151,Data!$B$2:$B$151,$A5) -> 64.984 | H5: =AVERAGEIFS(Data!$K$2:$K$151,Data!$B$2:$B$151,$A5) -> 194.668 | I5: =AVERAGEIFS(Data!$Q$2:$Q$151,Data!$B$2:$B$151,$A5) -> 0.6671513 | J5: =AVERAGEIFS(Data!$S$2:$S$151,Data!$B$2:$B$151,$A5) -> 0.24820115 | K5: =AVERAGEIFS(Data!$U$2:$U$151,Data!$B$2:$B$151,$A5) -> 0.021695709 | L5: =AVERAGEIFS(Data!$W$2:$W$151,Data!$B$2:$B$151,$A5) -> 0.075478425 | M5: =_xlfn.MAXIFS(Data!$X$2:$X$151,Data!$B$2:$B$151,$A5) -> 0.211 | N5: =AVERAGEIFS(Data!$Y$2:$Y$151,Data!$B$2:$B$151,$A5) -> 0.23719035 | O5: =AVERAGEIFS(Data!$AI$2:$AI$151,Data!$B$2:$B$151,$A5) -> 7.1704429 | P5: =_xlfn.MAXIFS(Data!$AJ$2:$AJ$151,Data!$B$2:$B$151,$A5) -> 22.441567 | Q5: =AVERAGEIFS(Data!$AK$2:$AK$151,Data!$B$2:$B$151,$A5) -> 6.3399275 | R5: =_xlfn.MAXIFS(Data!$AL$2:$AL$151,Data!$B$2:$B$151,$A5) -> 19.722399 | S5: =AVERAGEIFS(Data!$O$2:$O$151,Data!$B$2:$B$151,$A5) -> 1.7993333 | T5: =_xlfn.MAXIFS(Data!$P$2:$P$151,Data!$B$2:$B$151,$A5) -> 5.5 | U5: =AVERAGEIFS(Data!$AO$2:$AO$151,Data!$B$2:$B$151,$A5) -> 7.667334 | V5: =AVERAGEIFS(Data!$AQ$2:$AQ$151,Data!$B$2:$B$151,$A5) -> 42.073207 | W5: =AVERAGEIFS(Data!$AR$2:$AR$151,Data!$B$2:$B$151,$A5) -> 0.042073207 | X5: =AVERAGEIFS(Data!$AS$2:$AS$151,Data!$B$2:$B$151,$A5) -> 46.856612 | Y5: =AVERAGEIFS(Data!$AV$2:$AV$151,Data!$B$2:$B$151,$A5) -> 1.6158649
A6: 512 | B6: =AVERAGEIFS(Data!$H$2:$H$151,Data!$B$2:$B$151,$A6) -> 1644.7635 | C6: =AVERAGEIFS(Data!$F$2:$F$151,Data!$B$2:$B$151,$A6) -> 100.61797 | D6: =AVERAGEIFS(Data!$G$2:$G$151,Data!$B$2:$B$151,$A6) -> 41.018487 | E6: =AVERAGEIFS(Data!$E$2:$E$151,Data!$B$2:$B$151,$A6) -> 38.04 | F6: =AVERAGEIFS(Data!$AG$2:$AG$151,Data!$B$2:$B$151,$A6) -> 30.44 | G6: =AVERAGEIFS(Data!$I$2:$I$151,Data!$B$2:$B$151,$A6) -> 83.5 | H6: =AVERAGEIFS(Data!$K$2:$K$151,Data!$B$2:$B$151,$A6) -> 240.9 | I6: =AVERAGEIFS(Data!$Q$2:$Q$151,Data!$B$2:$B$151,$A6) -> 0.85104663 | J6: =AVERAGEIFS(Data!$S$2:$S$151,Data!$B$2:$B$151,$A6) -> 0.31214753 | K6: =AVERAGEIFS(Data!$U$2:$U$151,Data!$B$2:$B$151,$A6) -> 0.025852922 | L6: =AVERAGEIFS(Data!$W$2:$W$151,Data!$B$2:$B$151,$A6) -> 0.10467285 | M6: =_xlfn.MAXIFS(Data!$X$2:$X$151,Data!$B$2:$B$151,$A6) -> 0.209 | N6: =AVERAGEIFS(Data!$Y$2:$Y$151,Data!$B$2:$B$151,$A6) -> 0.31130368 | O6: =AVERAGEIFS(Data!$AI$2:$AI$151,Data!$B$2:$B$151,$A6) -> 9.4682073 | P6: =_xlfn.MAXIFS(Data!$AJ$2:$AJ$151,Data!$B$2:$B$151,$A6) -> 14.506231 | Q6: =AVERAGEIFS(Data!$AK$2:$AK$151,Data!$B$2:$B$151,$A6) -> 8.3380073 | R6: =_xlfn.MAXIFS(Data!$AL$2:$AL$151,Data!$B$2:$B$151,$A6) -> 13.009085 | S6: =AVERAGEIFS(Data!$O$2:$O$151,Data!$B$2:$B$151,$A6) -> 5.2216667 | T6: =_xlfn.MAXIFS(Data!$P$2:$P$151,Data!$B$2:$B$151,$A6) -> 16.4 | U6: =AVERAGEIFS(Data!$AO$2:$AO$151,Data!$B$2:$B$151,$A6) -> 5.8642621 | V6: =AVERAGEIFS(Data!$AQ$2:$AQ$151,Data!$B$2:$B$151,$A6) -> 57.566722 | W6: =AVERAGEIFS(Data!$AR$2:$AR$151,Data!$B$2:$B$151,$A6) -> 0.057566722 | X6: =AVERAGEIFS(Data!$AS$2:$AS$151,Data!$B$2:$B$151,$A6) -> 67.813268 | Y6: =AVERAGEIFS(Data!$AV$2:$AV$151,Data!$B$2:$B$151,$A6) -> 1.7106735
A7: 1024 | B7: =AVERAGEIFS(Data!$H$2:$H$151,Data!$B$2:$B$151,$A7) -> 1745.6628 | C7: =AVERAGEIFS(Data!$F$2:$F$151,Data!$B$2:$B$151,$A7) -> 100.48698 | D7: =AVERAGEIFS(Data!$G$2:$G$151,Data!$B$2:$B$151,$A7) -> 42.797139 | E7: =AVERAGEIFS(Data!$E$2:$E$151,Data!$B$2:$B$151,$A7) -> 65.6 | F7: =AVERAGEIFS(Data!$AG$2:$AG$151,Data!$B$2:$B$151,$A7) -> 58 | G7: =AVERAGEIFS(Data!$I$2:$I$151,Data!$B$2:$B$151,$A7) -> 89.572 | H7: =AVERAGEIFS(Data!$K$2:$K$151,Data!$B$2:$B$151,$A7) -> 248.728 | I7: =AVERAGEIFS(Data!$Q$2:$Q$151,Data!$B$2:$B$151,$A7) -> 0.90635162 | J7: =AVERAGEIFS(Data!$S$2:$S$151,Data!$B$2:$B$151,$A7) -> 0.3418756 | K7: =AVERAGEIFS(Data!$U$2:$U$151,Data!$B$2:$B$151,$A7) -> 0.027816352 | L7: =AVERAGEIFS(Data!$W$2:$W$151,Data!$B$2:$B$151,$A7) -> 0.11297213 | M7: =_xlfn.MAXIFS(Data!$X$2:$X$151,Data!$B$2:$B$151,$A7) -> 0.2 | N7: =AVERAGEIFS(Data!$Y$2:$Y$151,Data!$B$2:$B$151,$A7) -> 0.34541677 | O7: =AVERAGEIFS(Data!$AI$2:$AI$151,Data!$B$2:$B$151,$A7) -> 10.138133 | P7: =_xlfn.MAXIFS(Data!$AJ$2:$AJ$151,Data!$B$2:$B$151,$A7) -> 15.220625 | Q7: =AVERAGEIFS(Data!$AK$2:$AK$151,Data!$B$2:$B$151,$A7) -> 8.9064889 | R7: =_xlfn.MAXIFS(Data!$AL$2:$AL$151,Data!$B$2:$B$151,$A7) -> 13.667288 | S7: =AVERAGEIFS(Data!$O$2:$O$151,Data!$B$2:$B$151,$A7) -> 8.2708762 | T7: =_xlfn.MAXIFS(Data!$P$2:$P$151,Data!$B$2:$B$151,$A7) -> 20.7 | U7: =AVERAGEIFS(Data!$AO$2:$AO$151,Data!$B$2:$B$151,$A7) -> 5.8356722 | V7: =AVERAGEIFS(Data!$AQ$2:$AQ$151,Data!$B$2:$B$151,$A7) -> 61.098198 | W7: =AVERAGEIFS(Data!$AR$2:$AR$151,Data!$B$2:$B$151,$A7) -> 0.061098198 | X7: =AVERAGEIFS(Data!$AS$2:$AS$151,Data!$B$2:$B$151,$A7) -> 74.727636 | Y7: =AVERAGEIFS(Data!$AV$2:$AV$151,Data!$B$2:$B$151,$A7) -> 1.7575209
A8: 2048 | B8: =AVERAGEIFS(Data!$H$2:$H$151,Data!$B$2:$B$151,$A8) -> 1730.0949 | C8: =AVERAGEIFS(Data!$F$2:$F$151,Data!$B$2:$B$151,$A8) -> 112.22658 | D8: =AVERAGEIFS(Data!$G$2:$G$151,Data!$B$2:$B$151,$A8) -> 45.649726 | E8: =AVERAGEIFS(Data!$E$2:$E$151,Data!$B$2:$B$151,$A8) -> 124.4 | F8: =AVERAGEIFS(Data!$AG$2:$AG$151,Data!$B$2:$B$151,$A8) -> 116.8 | G8: =AVERAGEIFS(Data!$I$2:$I$151,Data!$B$2:$B$151,$A8) -> 94.888 | H8: =AVERAGEIFS(Data!$K$2:$K$151,Data!$B$2:$B$151,$A8) -> 261.3 | I8: =AVERAGEIFS(Data!$Q$2:$Q$151,Data!$B$2:$B$151,$A8) -> 0.95153571 | J8: =AVERAGEIFS(Data!$S$2:$S$151,Data!$B$2:$B$151,$A8) -> 0.38288777 | K8: =AVERAGEIFS(Data!$U$2:$U$151,Data!$B$2:$B$151,$A8) -> 0.030272158 | L8: =AVERAGEIFS(Data!$W$2:$W$151,Data!$B$2:$B$151,$A8) -> 0.1231141 | M8: =_xlfn.MAXIFS(Data!$X$2:$X$151,Data!$B$2:$B$151,$A8) -> 0.235 | N8: =AVERAGEIFS(Data!$Y$2:$Y$151,Data!$B$2:$B$151,$A8) -> 0.38776137 | O8: =AVERAGEIFS(Data!$AI$2:$AI$151,Data!$B$2:$B$151,$A8) -> 10.372365 | P8: =_xlfn.MAXIFS(Data!$AJ$2:$AJ$151,Data!$B$2:$B$151,$A8) -> 22.223756 | Q8: =AVERAGEIFS(Data!$AK$2:$AK$151,Data!$B$2:$B$151,$A8) -> 9.0922152 | R8: =_xlfn.MAXIFS(Data!$AL$2:$AL$151,Data!$B$2:$B$151,$A8) -> 19.456527 | S8: =AVERAGEIFS(Data!$O$2:$O$151,Data!$B$2:$B$151,$A8) -> 13.7737 | T8: =_xlfn.MAXIFS(Data!$P$2:$P$151,Data!$B$2:$B$151,$A8) -> 29.7 | U8: =AVERAGEIFS(Data!$AO$2:$AO$151,Data!$B$2:$B$151,$A8) -> 6.0076881 | V8: =AVERAGEIFS(Data!$AQ$2:$AQ$151,Data!$B$2:$B$151,$A8) -> 60.553322 | W8: =AVERAGEIFS(Data!$AR$2:$AR$151,Data!$B$2:$B$151,$A8) -> 0.060553322 | X8: =AVERAGEIFS(Data!$AS$2:$AS$151,Data!$B$2:$B$151,$A8) -> 78.879205 | Y8: =AVERAGEIFS(Data!$AV$2:$AV$151,Data!$B$2:$B$151,$A8) -> 1.6563738
A9: 5120 | B9: =AVERAGEIFS(Data!$H$2:$H$151,Data!$B$2:$B$151,$A9) -> 1539.4008 | C9: =AVERAGEIFS(Data!$F$2:$F$151,Data!$B$2:$B$151,$A9) -> 99.058662 | D9: =AVERAGEIFS(Data!$G$2:$G$151,Data!$B$2:$B$151,$A9) -> 52.667852 | E9: =AVERAGEIFS(Data!$E$2:$E$151,Data!$B$2:$B$151,$A9) -> 340.6 | F9: =AVERAGEIFS(Data!$AG$2:$AG$151,Data!$B$2:$B$151,$A9) -> 333 | G9: =AVERAGEIFS(Data!$I$2:$I$151,Data!$B$2:$B$151,$A9) -> 97.276 | H9: =AVERAGEIFS(Data!$K$2:$K$151,Data!$B$2:$B$151,$A9) -> 282.696 | I9: =AVERAGEIFS(Data!$Q$2:$Q$151,Data!$B$2:$B$151,$A9) -> 0.97255526 | J9: =AVERAGEIFS(Data!$S$2:$S$151,Data!$B$2:$B$151,$A9) -> 0.45909452 | K9: =AVERAGEIFS(Data!$U$2:$U$151,Data!$B$2:$B$151,$A9) -> 0.034072053 | L9: =AVERAGEIFS(Data!$W$2:$W$151,Data!$B$2:$B$151,$A9) -> 0.13521571 | M9: =_xlfn.MAXIFS(Data!$X$2:$X$151,Data!$B$2:$B$151,$A9) -> 0.201 | N9: =AVERAGEIFS(Data!$Y$2:$Y$151,Data!$B$2:$B$151,$A9) -> 0.46553852 | O9: =AVERAGEIFS(Data!$AI$2:$AI$151,Data!$B$2:$B$151,$A9) -> 9.1925105 | P9: =_xlfn.MAXIFS(Data!$AJ$2:$AJ$151,Data!$B$2:$B$151,$A9) -> 14.451115 | Q9: =AVERAGEIFS(Data!$AK$2:$AK$151,Data!$B$2:$B$151,$A9) -> 8.0611484 | R9: =_xlfn.MAXIFS(Data!$AL$2:$AL$151,Data!$B$2:$B$151,$A9) -> 12.881256 | S9: =AVERAGEIFS(Data!$O$2:$O$151,Data!$B$2:$B$151,$A9) -> 30.202745 | T9: =_xlfn.MAXIFS(Data!$P$2:$P$151,Data!$B$2:$B$151,$A9) -> 56.4 | U9: =AVERAGEIFS(Data!$AO$2:$AO$151,Data!$B$2:$B$151,$A9) -> 5.9701602 | V9: =AVERAGEIFS(Data!$AQ$2:$AQ$151,Data!$B$2:$B$151,$A9) -> 53.879028 | W9: =AVERAGEIFS(Data!$AR$2:$AR$151,Data!$B$2:$B$151,$A9) -> 0.053879028 | X9: =AVERAGEIFS(Data!$AS$2:$AS$151,Data!$B$2:$B$151,$A9) -> 81.012276 | Y9: =AVERAGEIFS(Data!$AV$2:$AV$151,Data!$B$2:$B$151,$A9) -> 1.3621406
A10: 10240 | B10: =AVERAGEIFS(Data!$H$2:$H$151,Data!$B$2:$B$151,$A10) -> 1261.0638 | C10: =AVERAGEIFS(Data!$F$2:$F$151,Data!$B$2:$B$151,$A10) -> 532.80606 | D10: =AVERAGEIFS(Data!$G$2:$G$151,Data!$B$2:$B$151,$A10) -> 64.729269 | E10: =AVERAGEIFS(Data!$E$2:$E$151,Data!$B$2:$B$151,$A10) -> 815.32 | F10: =AVERAGEIFS(Data!$AG$2:$AG$151,Data!$B$2:$B$151,$A10) -> 807.72 | G10: =AVERAGEIFS(Data!$I$2:$I$151,Data!$B$2:$B$151,$A10) -> 99.084 | H10: =AVERAGEIFS(Data!$K$2:$K$151,Data!$B$2:$B$151,$A10) -> 304.228 | I10: =AVERAGEIFS(Data!$Q$2:$Q$151,Data!$B$2:$B$151,$A10) -> 0.98945083 | J10: =AVERAGEIFS(Data!$S$2:$S$151,Data!$B$2:$B$151,$A10) -> 0.54902618 | K10: =AVERAGEIFS(Data!$U$2:$U$151,Data!$B$2:$B$151,$A10) -> 0.038857205 | L10: =AVERAGEIFS(Data!$W$2:$W$151,Data!$B$2:$B$151,$A10) -> 0.14968952 | M10: =_xlfn.MAXIFS(Data!$X$2:$X$151,Data!$B$2:$B$151,$A10) -> 0.245 | N10: =AVERAGEIFS(Data!$Y$2:$Y$151,Data!$B$2:$B$151,$A10) -> 0.55460388 | O10: =AVERAGEIFS(Data!$AI$2:$AI$151,Data!$B$2:$B$151,$A10) -> 7.7047759 | P10: =_xlfn.MAXIFS(Data!$AJ$2:$AJ$151,Data!$B$2:$B$151,$A10) -> 31.174143 | Q10: =AVERAGEIFS(Data!$AK$2:$AK$151,Data!$B$2:$B$151,$A10) -> 6.756506 | R10: =_xlfn.MAXIFS(Data!$AL$2:$AL$151,Data!$B$2:$B$151,$A10) -> 27.279864 | S10: =AVERAGEIFS(Data!$O$2:$O$151,Data!$B$2:$B$151,$A10) -> 58.631426 | T10: =_xlfn.MAXIFS(Data!$P$2:$P$151,Data!$B$2:$B$151,$A10) -> 100 | U10: =AVERAGEIFS(Data!$AO$2:$AO$151,Data!$B$2:$B$151,$A10) -> 6.1114665 | V10: =AVERAGEIFS(Data!$AQ$2:$AQ$151,Data!$B$2:$B$151,$A10) -> 44.137231 | W10: =AVERAGEIFS(Data!$AR$2:$AR$151,Data!$B$2:$B$151,$A10) -> 0.044137231 | X10: =AVERAGEIFS(Data!$AS$2:$AS$151,Data!$B$2:$B$151,$A10) -> 81.572578 | Y10: =AVERAGEIFS(Data!$AV$2:$AV$151,Data!$B$2:$B$151,$A10) -> 1.0366428

Sheet By_Input_Len
A1: Averages by input length
A2: Each row averages the 30 load points (6 output lengths x 5 rates) that share that input length.
A4: input_len | B4: Output throughput (tok/s) | C4: Mean TTFT (ms) | D4: Mean TPOT (ms) | E4: Elapsed (s) | F4: Elapsed minus arrival window (s) | G4: Avg GPU util (%) | H4: Avg power (W) | I4: GR engine active (avg) | J4: SM active (avg) | K4: SM occupancy (avg) | L4: Tensor active (avg) | M4: Tensor active (max peak) | N4: DRAM active (avg) | O4: PCIe TX avg (GB/s) | P4: PCIe TX peak (GB/s, max) | Q4: PCIe RX avg (GB/s) | R4: PCIe RX peak (GB/s, max) | S4: KV cache in use, avg (%) | T4: KV cache in use, peak (%, max) | U4: PCIe TX per token (MB per GPU) | V4: Achieved TFLOPS per GPU | W4: % of est. dense FP8 peak | X4: Concurrent sequences (Little) | Y4: Tokens per joule
A5: 128 | B5: =AVERAGEIFS(Data!$H$2:$H$151,Data!$A$2:$A$151,$A5) -> 1569.035 | C5: =AVERAGEIFS(Data!$F$2:$F$151,Data!$A$2:$A$151,$A5) -> 99.301983 | D5: =AVERAGEIFS(Data!$G$2:$G$151,Data!$A$2:$A$151,$A5) -> 45.44032 | E5: =AVERAGEIFS(Data!$E$2:$E$151,Data!$A$2:$A$151,$A5) -> 226.76667 | F5: =AVERAGEIFS(Data!$AG$2:$AG$151,Data!$A$2:$A$151,$A5) -> 219.16667 | G5: =AVERAGEIFS(Data!$I$2:$I$151,Data!$A$2:$A$151,$A5) -> 88.336667 | H5: =AVERAGEIFS(Data!$K$2:$K$151,Data!$A$2:$A$151,$A5) -> 252.28667 | I5: =AVERAGEIFS(Data!$Q$2:$Q$151,Data!$A$2:$A$151,$A5) -> 0.89240355 | J5: =AVERAGEIFS(Data!$S$2:$S$151,Data!$A$2:$A$151,$A5) -> 0.36928613 | K5: =AVERAGEIFS(Data!$U$2:$U$151,Data!$A$2:$A$151,$A5) -> 0.029167834 | L5: =AVERAGEIFS(Data!$W$2:$W$151,Data!$A$2:$A$151,$A5) -> 0.11423548 | M5: =_xlfn.MAXIFS(Data!$X$2:$X$151,Data!$A$2:$A$151,$A5) -> 0.18 | N5: =AVERAGEIFS(Data!$Y$2:$Y$151,Data!$A$2:$A$151,$A5) -> 0.37547361 | O5: =AVERAGEIFS(Data!$AI$2:$AI$151,Data!$A$2:$A$151,$A5) -> 9.2419068 | P5: =_xlfn.MAXIFS(Data!$AJ$2:$AJ$151,Data!$A$2:$A$151,$A5) -> 17.484962 | Q5: =AVERAGEIFS(Data!$AK$2:$AK$151,Data!$A$2:$A$151,$A5) -> 8.1202126 | R5: =_xlfn.MAXIFS(Data!$AL$2:$AL$151,Data!$A$2:$A$151,$A5) -> 15.313969 | S5: =AVERAGEIFS(Data!$O$2:$O$151,Data!$A$2:$A$151,$A5) -> 17.03312 | T5: =_xlfn.MAXIFS(Data!$P$2:$P$151,Data!$A$2:$A$151,$A5) -> 89.1 | U5: =AVERAGEIFS(Data!$AO$2:$AO$151,Data!$A$2:$A$151,$A5) -> 6.1454276 | V5: =AVERAGEIFS(Data!$AQ$2:$AQ$151,Data!$A$2:$A$151,$A5) -> 54.916226 | W5: =AVERAGEIFS(Data!$AR$2:$AR$151,Data!$A$2:$A$151,$A5) -> 0.054916226 | X5: =AVERAGEIFS(Data!$AS$2:$AS$151,Data!$A$2:$A$151,$A5) -> 71.118549 | Y5: =AVERAGEIFS(Data!$AV$2:$AV$151,Data!$A$2:$A$151,$A5) -> 1.5931918
A6: 256 | B6: =AVERAGEIFS(Data!$H$2:$H$151,Data!$A$2:$A$151,$A6) -> 1549.0025 | C6: =AVERAGEIFS(Data!$F$2:$F$151,Data!$A$2:$A$151,$A6) -> 115.13928 | D6: =AVERAGEIFS(Data!$G$2:$G$151,Data!$A$2:$A$151,$A6) -> 46.161028 | E6: =AVERAGEIFS(Data!$E$2:$E$151,Data!$A$2:$A$151,$A6) -> 229.63333 | F6: =AVERAGEIFS(Data!$AG$2:$AG$151,Data!$A$2:$A$151,$A6) -> 222.03333 | G6: =AVERAGEIFS(Data!$I$2:$I$151,Data!$A$2:$A$151,$A6) -> 87.91 | H6: =AVERAGEIFS(Data!$K$2:$K$151,Data!$A$2:$A$151,$A6) -> 253.39667 | I6: =AVERAGEIFS(Data!$Q$2:$Q$151,Data!$A$2:$A$151,$A6) -> 0.88688756 | J6: =AVERAGEIFS(Data!$S$2:$S$151,Data!$A$2:$A$151,$A6) -> 0.37313064 | K6: =AVERAGEIFS(Data!$U$2:$U$151,Data!$A$2:$A$151,$A6) -> 0.029184049 | L6: =AVERAGEIFS(Data!$W$2:$W$151,Data!$A$2:$A$151,$A6) -> 0.11437381 | M6: =_xlfn.MAXIFS(Data!$X$2:$X$151,Data!$A$2:$A$151,$A6) -> 0.224 | N6: =AVERAGEIFS(Data!$Y$2:$Y$151,Data!$A$2:$A$151,$A6) -> 0.37528255 | O6: =AVERAGEIFS(Data!$AI$2:$AI$151,Data!$A$2:$A$151,$A6) -> 9.0861703 | P6: =_xlfn.MAXIFS(Data!$AJ$2:$AJ$151,Data!$A$2:$A$151,$A6) -> 22.219695 | Q6: =AVERAGEIFS(Data!$AK$2:$AK$151,Data!$A$2:$A$151,$A6) -> 7.9843373 | R6: =_xlfn.MAXIFS(Data!$AL$2:$AL$151,Data!$A$2:$A$151,$A6) -> 19.476238 | S6: =AVERAGEIFS(Data!$O$2:$O$151,Data!$A$2:$A$151,$A6) -> 18.125028 | T6: =_xlfn.MAXIFS(Data!$P$2:$P$151,Data!$A$2:$A$151,$A6) -> 90.8 | U6: =AVERAGEIFS(Data!$AO$2:$AO$151,Data!$A$2:$A$151,$A6) -> 6.1474083 | V6: =AVERAGEIFS(Data!$AQ$2:$AQ$151,Data!$A$2:$A$151,$A6) -> 54.215089 | W6: =AVERAGEIFS(Data!$AR$2:$AR$151,Data!$A$2:$A$151,$A6) -> 0.054215089 | X6: =AVERAGEIFS(Data!$AS$2:$AS$151,Data!$A$2:$A$151,$A6) -> 71.351939 | Y6: =AVERAGEIFS(Data!$AV$2:$AV$151,Data!$A$2:$A$151,$A6) -> 1.5672096
A7: 384 | B7: =AVERAGEIFS(Data!$H$2:$H$151,Data!$A$2:$A$151,$A7) -> 1530.7337 | C7: =AVERAGEIFS(Data!$F$2:$F$151,Data!$A$2:$A$151,$A7) -> 139.97264 | D7: =AVERAGEIFS(Data!$G$2:$G$151,Data!$A$2:$A$151,$A7) -> 46.858273 | E7: =AVERAGEIFS(Data!$E$2:$E$151,Data!$A$2:$A$151,$A7) -> 231.73333 | F7: =AVERAGEIFS(Data!$AG$2:$AG$151,Data!$A$2:$A$151,$A7) -> 224.13333 | G7: =AVERAGEIFS(Data!$I$2:$I$151,Data!$A$2:$A$151,$A7) -> 88.03 | H7: =AVERAGEIFS(Data!$K$2:$K$151,Data!$A$2:$A$151,$A7) -> 254.78333 | I7: =AVERAGEIFS(Data!$Q$2:$Q$151,Data!$A$2:$A$151,$A7) -> 0.8891425 | J7: =AVERAGEIFS(Data!$S$2:$S$151,Data!$A$2:$A$151,$A7) -> 0.38026816 | K7: =AVERAGEIFS(Data!$U$2:$U$151,Data!$A$2:$A$151,$A7) -> 0.029658876 | L7: =AVERAGEIFS(Data!$W$2:$W$151,Data!$A$2:$A$151,$A7) -> 0.11590727 | M7: =_xlfn.MAXIFS(Data!$X$2:$X$151,Data!$A$2:$A$151,$A7) -> 0.244 | N7: =AVERAGEIFS(Data!$Y$2:$Y$151,Data!$A$2:$A$151,$A7) -> 0.38263326 | O7: =AVERAGEIFS(Data!$AI$2:$AI$151,Data!$A$2:$A$151,$A7) -> 9.0377345 | P7: =_xlfn.MAXIFS(Data!$AJ$2:$AJ$151,Data!$A$2:$A$151,$A7) -> 28.580553 | Q7: =AVERAGEIFS(Data!$AK$2:$AK$151,Data!$A$2:$A$151,$A7) -> 7.9426904 | R7: =_xlfn.MAXIFS(Data!$AL$2:$AL$151,Data!$A$2:$A$151,$A7) -> 25.012029 | S7: =AVERAGEIFS(Data!$O$2:$O$151,Data!$A$2:$A$151,$A7) -> 19.095651 | T7: =_xlfn.MAXIFS(Data!$P$2:$P$151,Data!$A$2:$A$151,$A7) -> 92 | U7: =AVERAGEIFS(Data!$AO$2:$AO$151,Data!$A$2:$A$151,$A7) -> 6.1768663 | V7: =AVERAGEIFS(Data!$AQ$2:$AQ$151,Data!$A$2:$A$151,$A7) -> 53.57568 | W7: =AVERAGEIFS(Data!$AR$2:$AR$151,Data!$A$2:$A$151,$A7) -> 0.05357568 | X7: =AVERAGEIFS(Data!$AS$2:$AS$151,Data!$A$2:$A$151,$A7) -> 71.592026 | Y7: =AVERAGEIFS(Data!$AV$2:$AV$151,Data!$A$2:$A$151,$A7) -> 1.5361434
A8: 512 | B8: =AVERAGEIFS(Data!$H$2:$H$151,Data!$A$2:$A$151,$A8) -> 1512.0925 | C8: =AVERAGEIFS(Data!$F$2:$F$151,Data!$A$2:$A$151,$A8) -> 173.38467 | D8: =AVERAGEIFS(Data!$G$2:$G$151,Data!$A$2:$A$151,$A8) -> 47.590116 | E8: =AVERAGEIFS(Data!$E$2:$E$151,Data!$A$2:$A$151,$A8) -> 234.3 | F8: =AVERAGEIFS(Data!$AG$2:$AG$151,Data!$A$2:$A$151,$A8) -> 226.7 | G8: =AVERAGEIFS(Data!$I$2:$I$151,Data!$A$2:$A$151,$A8) -> 88.536667 | H8: =AVERAGEIFS(Data!$K$2:$K$151,Data!$A$2:$A$151,$A8) -> 256.30333 | I8: =AVERAGEIFS(Data!$Q$2:$Q$151,Data!$A$2:$A$151,$A8) -> 0.8931201 | J8: =AVERAGEIFS(Data!$S$2:$S$151,Data!$A$2:$A$151,$A8) -> 0.38631757 | K8: =AVERAGEIFS(Data!$U$2:$U$151,Data!$A$2:$A$151,$A8) -> 0.02995969 | L8: =AVERAGEIFS(Data!$W$2:$W$151,Data!$A$2:$A$151,$A8) -> 0.11732555 | M8: =_xlfn.MAXIFS(Data!$X$2:$X$151,Data!$A$2:$A$151,$A8) -> 0.238 | N8: =AVERAGEIFS(Data!$Y$2:$Y$151,Data!$A$2:$A$151,$A8) -> 0.38702866 | O8: =AVERAGEIFS(Data!$AI$2:$AI$151,Data!$A$2:$A$151,$A8) -> 8.9420394 | P8: =_xlfn.MAXIFS(Data!$AJ$2:$AJ$151,Data!$A$2:$A$151,$A8) -> 30.127833 | Q8: =AVERAGEIFS(Data!$AK$2:$AK$151,Data!$A$2:$A$151,$A8) -> 7.8591048 | R8: =_xlfn.MAXIFS(Data!$AL$2:$AL$151,Data!$A$2:$A$151,$A8) -> 26.365587 | S8: =AVERAGEIFS(Data!$O$2:$O$151,Data!$A$2:$A$151,$A8) -> 19.939281 | T8: =_xlfn.MAXIFS(Data!$P$2:$P$151,Data!$A$2:$A$151,$A8) -> 93.9 | U8: =AVERAGEIFS(Data!$AO$2:$AO$151,Data!$A$2:$A$151,$A8) -> 6.1829712 | V8: =AVERAGEIFS(Data!$AQ$2:$AQ$151,Data!$A$2:$A$151,$A8) -> 52.923237 | W8: =AVERAGEIFS(Data!$AR$2:$AR$151,Data!$A$2:$A$151,$A8) -> 0.052923237 | X8: =AVERAGEIFS(Data!$AS$2:$AS$151,Data!$A$2:$A$151,$A8) -> 71.851616 | Y8: =AVERAGEIFS(Data!$AV$2:$AV$151,Data!$A$2:$A$151,$A8) -> 1.5072406
A9: 1024 | B9: =AVERAGEIFS(Data!$H$2:$H$151,Data!$A$2:$A$151,$A9) -> 1441.7007 | C9: =AVERAGEIFS(Data!$F$2:$F$151,Data!$A$2:$A$151,$A9) -> 348.48606 | D9: =AVERAGEIFS(Data!$G$2:$G$151,Data!$A$2:$A$151,$A9) -> 51.172654 | E9: =AVERAGEIFS(Data!$E$2:$E$151,Data!$A$2:$A$151,$A9) -> 246.83333 | F9: =AVERAGEIFS(Data!$AG$2:$AG$151,Data!$A$2:$A$151,$A9) -> 239.23333 | G9: =AVERAGEIFS(Data!$I$2:$I$151,Data!$A$2:$A$151,$A9) -> 88.273333 | H9: =AVERAGEIFS(Data!$K$2:$K$151,Data!$A$2:$A$151,$A9) -> 260.33 | I9: =AVERAGEIFS(Data!$Q$2:$Q$151,Data!$A$2:$A$151,$A9) -> 0.88685573 | J9: =AVERAGEIFS(Data!$S$2:$S$151,Data!$A$2:$A$151,$A9) -> 0.4020248 | K9: =AVERAGEIFS(Data!$U$2:$U$151,Data!$A$2:$A$151,$A9) -> 0.030834882 | L9: =AVERAGEIFS(Data!$W$2:$W$151,Data!$A$2:$A$151,$A9) -> 0.12244351 | M9: =_xlfn.MAXIFS(Data!$X$2:$X$151,Data!$A$2:$A$151,$A9) -> 0.245 | N9: =AVERAGEIFS(Data!$Y$2:$Y$151,Data!$A$2:$A$151,$A9) -> 0.39776072 | O9: =AVERAGEIFS(Data!$AI$2:$AI$151,Data!$A$2:$A$151,$A9) -> 8.7308449 | P9: =_xlfn.MAXIFS(Data!$AJ$2:$AJ$151,Data!$A$2:$A$151,$A9) -> 31.174143 | Q9: =AVERAGEIFS(Data!$AK$2:$AK$151,Data!$A$2:$A$151,$A9) -> 7.6722327 | R9: =_xlfn.MAXIFS(Data!$AL$2:$AL$151,Data!$A$2:$A$151,$A9) -> 27.279864 | S9: =AVERAGEIFS(Data!$O$2:$O$151,Data!$A$2:$A$151,$A9) -> 24.05671 | T9: =_xlfn.MAXIFS(Data!$P$2:$P$151,Data!$A$2:$A$151,$A9) -> 100 | U9: =AVERAGEIFS(Data!$AO$2:$AO$151,Data!$A$2:$A$151,$A9) -> 6.5611459 | V9: =AVERAGEIFS(Data!$AQ$2:$AQ$151,Data!$A$2:$A$151,$A9) -> 50.459525 | W9: =AVERAGEIFS(Data!$AR$2:$AR$151,Data!$A$2:$A$151,$A9) -> 0.050459525 | X9: =AVERAGEIFS(Data!$AS$2:$AS$151,Data!$A$2:$A$151,$A9) -> 73.137184 | Y9: =AVERAGEIFS(Data!$AV$2:$AV$151,Data!$A$2:$A$151,$A9) -> 1.4122284

Sheet By_Rate
A1: Averages by request rate
A2: Each row averages the 30 load points that share that request rate. Compare "Elapsed minus arrival window", not raw elapsed time.
A4: rate_rps | B4: Output throughput (tok/s) | C4: Mean TTFT (ms) | D4: Mean TPOT (ms) | E4: Elapsed (s) | F4: Elapsed minus arrival window (s) | G4: Avg GPU util (%) | H4: Avg power (W) | I4: GR engine active (avg) | J4: SM active (avg) | K4: SM occupancy (avg) | L4: Tensor active (avg) | M4: Tensor active (max peak) | N4: DRAM active (avg) | O4: PCIe TX avg (GB/s) | P4: PCIe TX peak (GB/s, max) | Q4: PCIe RX avg (GB/s) | R4: PCIe RX peak (GB/s, max) | S4: KV cache in use, avg (%) | T4: KV cache in use, peak (%, max) | U4: PCIe TX per token (MB per GPU) | V4: Achieved TFLOPS per GPU | W4: % of est. dense FP8 peak | X4: Concurrent sequences (Little) | Y4: Tokens per joule
A5: 5 | B5: =AVERAGEIFS(Data!$H$2:$H$151,Data!$C$2:$C$151,$A5) -> 1273.5827 | C5: =AVERAGEIFS(Data!$F$2:$F$151,Data!$C$2:$C$151,$A5) -> 129.01385 | D5: =AVERAGEIFS(Data!$G$2:$G$151,Data!$C$2:$C$151,$A5) -> 45.873097 | E5: =AVERAGEIFS(Data!$E$2:$E$151,Data!$C$2:$C$151,$A5) -> 241.86667 | F5: =AVERAGEIFS(Data!$AG$2:$AG$151,Data!$C$2:$C$151,$A5) -> 221.86667 | G5: =AVERAGEIFS(Data!$I$2:$I$151,Data!$C$2:$C$151,$A5) -> 91.366667 | H5: =AVERAGEIFS(Data!$K$2:$K$151,Data!$C$2:$C$151,$A5) -> 262.56 | I5: =AVERAGEIFS(Data!$Q$2:$Q$151,Data!$C$2:$C$151,$A5) -> 0.92050268 | J5: =AVERAGEIFS(Data!$S$2:$S$151,Data!$C$2:$C$151,$A5) -> 0.41070861 | K5: =AVERAGEIFS(Data!$U$2:$U$151,Data!$C$2:$C$151,$A5) -> 0.033079379 | L5: =AVERAGEIFS(Data!$W$2:$W$151,Data!$C$2:$C$151,$A5) -> 0.11798822 | M5: =_xlfn.MAXIFS(Data!$X$2:$X$151,Data!$C$2:$C$151,$A5) -> 0.244 | N5: =AVERAGEIFS(Data!$Y$2:$Y$151,Data!$C$2:$C$151,$A5) -> 0.40445354 | O5: =AVERAGEIFS(Data!$AI$2:$AI$151,Data!$C$2:$C$151,$A5) -> 9.1693318 | P5: =_xlfn.MAXIFS(Data!$AJ$2:$AJ$151,Data!$C$2:$C$151,$A5) -> 26.610549 | Q5: =AVERAGEIFS(Data!$AK$2:$AK$151,Data!$C$2:$C$151,$A5) -> 8.0757043 | R5: =_xlfn.MAXIFS(Data!$AL$2:$AL$151,Data!$C$2:$C$151,$A5) -> 23.303594 | S5: =AVERAGEIFS(Data!$O$2:$O$151,Data!$C$2:$C$151,$A5) -> 18.683687 | T5: =_xlfn.MAXIFS(Data!$P$2:$P$151,Data!$C$2:$C$151,$A5) -> 99.6 | U5: =AVERAGEIFS(Data!$AO$2:$AO$151,Data!$C$2:$C$151,$A5) -> 8.2148411 | V5: =AVERAGEIFS(Data!$AQ$2:$AQ$151,Data!$C$2:$C$151,$A5) -> 44.575395 | W5: =AVERAGEIFS(Data!$AR$2:$AR$151,Data!$C$2:$C$151,$A5) -> 0.044575395 | X5: =AVERAGEIFS(Data!$AS$2:$AS$151,Data!$C$2:$C$151,$A5) -> 59.910187 | Y5: =AVERAGEIFS(Data!$AV$2:$AV$151,Data!$C$2:$C$151,$A5) -> 1.2045466
A6: 10 | B6: =AVERAGEIFS(Data!$H$2:$H$151,Data!$C$2:$C$151,$A6) -> 1433.106 | C6: =AVERAGEIFS(Data!$F$2:$F$151,Data!$C$2:$C$151,$A6) -> 108.59341 | D6: =AVERAGEIFS(Data!$G$2:$G$151,Data!$C$2:$C$151,$A6) -> 46.721866 | E6: =AVERAGEIFS(Data!$E$2:$E$151,Data!$C$2:$C$151,$A6) -> 234.53333 | F6: =AVERAGEIFS(Data!$AG$2:$AG$151,Data!$C$2:$C$151,$A6) -> 224.53333 | G6: =AVERAGEIFS(Data!$I$2:$I$151,Data!$C$2:$C$151,$A6) -> 89.433333 | H6: =AVERAGEIFS(Data!$K$2:$K$151,Data!$C$2:$C$151,$A6) -> 256.89333 | I6: =AVERAGEIFS(Data!$Q$2:$Q$151,Data!$C$2:$C$151,$A6) -> 0.90235165 | J6: =AVERAGEIFS(Data!$S$2:$S$151,Data!$C$2:$C$151,$A6) -> 0.3936605 | K6: =AVERAGEIFS(Data!$U$2:$U$151,Data!$C$2:$C$151,$A6) -> 0.03064839 | L6: =AVERAGEIFS(Data!$W$2:$W$151,Data!$C$2:$C$151,$A6) -> 0.11480809 | M6: =_xlfn.MAXIFS(Data!$X$2:$X$151,Data!$C$2:$C$151,$A6) -> 0.236 | N6: =AVERAGEIFS(Data!$Y$2:$Y$151,Data!$C$2:$C$151,$A6) -> 0.39376682 | O6: =AVERAGEIFS(Data!$AI$2:$AI$151,Data!$C$2:$C$151,$A6) -> 9.005608 | P6: =_xlfn.MAXIFS(Data!$AJ$2:$AJ$151,Data!$C$2:$C$151,$A6) -> 27.297797 | Q6: =AVERAGEIFS(Data!$AK$2:$AK$151,Data!$C$2:$C$151,$A6) -> 7.9242734 | R6: =_xlfn.MAXIFS(Data!$AL$2:$AL$151,Data!$C$2:$C$151,$A6) -> 23.901146 | S6: =AVERAGEIFS(Data!$O$2:$O$151,Data!$C$2:$C$151,$A6) -> 19.204447 | T6: =_xlfn.MAXIFS(Data!$P$2:$P$151,Data!$C$2:$C$151,$A6) -> 100 | U6: =AVERAGEIFS(Data!$AO$2:$AO$151,Data!$C$2:$C$151,$A6) -> 6.4566316 | V6: =AVERAGEIFS(Data!$AQ$2:$AQ$151,Data!$C$2:$C$151,$A6) -> 50.158709 | W6: =AVERAGEIFS(Data!$AR$2:$AR$151,Data!$C$2:$C$151,$A6) -> 0.050158709 | X6: =AVERAGEIFS(Data!$AS$2:$AS$151,Data!$C$2:$C$151,$A6) -> 67.275088 | Y6: =AVERAGEIFS(Data!$AV$2:$AV$151,Data!$C$2:$C$151,$A6) -> 1.3985595
A7: 20 | B7: =AVERAGEIFS(Data!$H$2:$H$151,Data!$C$2:$C$151,$A7) -> 1554.3864 | C7: =AVERAGEIFS(Data!$F$2:$F$151,Data!$C$2:$C$151,$A7) -> 137.55457 | D7: =AVERAGEIFS(Data!$G$2:$G$151,Data!$C$2:$C$151,$A7) -> 47.69242 | E7: =AVERAGEIFS(Data!$E$2:$E$151,Data!$C$2:$C$151,$A7) -> 231.76667 | F7: =AVERAGEIFS(Data!$AG$2:$AG$151,Data!$C$2:$C$151,$A7) -> 226.76667 | G7: =AVERAGEIFS(Data!$I$2:$I$151,Data!$C$2:$C$151,$A7) -> 87.14 | H7: =AVERAGEIFS(Data!$K$2:$K$151,Data!$C$2:$C$151,$A7) -> 254.62 | I7: =AVERAGEIFS(Data!$Q$2:$Q$151,Data!$C$2:$C$151,$A7) -> 0.8822003 | J7: =AVERAGEIFS(Data!$S$2:$S$151,Data!$C$2:$C$151,$A7) -> 0.37863691 | K7: =AVERAGEIFS(Data!$U$2:$U$151,Data!$C$2:$C$151,$A7) -> 0.02919483 | L7: =AVERAGEIFS(Data!$W$2:$W$151,Data!$C$2:$C$151,$A7) -> 0.116957 | M7: =_xlfn.MAXIFS(Data!$X$2:$X$151,Data!$C$2:$C$151,$A7) -> 0.245 | N7: =AVERAGEIFS(Data!$Y$2:$Y$151,Data!$C$2:$C$151,$A7) -> 0.38020739 | O7: =AVERAGEIFS(Data!$AI$2:$AI$151,Data!$C$2:$C$151,$A7) -> 8.8839335 | P7: =_xlfn.MAXIFS(Data!$AJ$2:$AJ$151,Data!$C$2:$C$151,$A7) -> 30.119905 | Q7: =AVERAGEIFS(Data!$AK$2:$AK$151,Data!$C$2:$C$151,$A7) -> 7.8044965 | R7: =_xlfn.MAXIFS(Data!$AL$2:$AL$151,Data!$C$2:$C$151,$A7) -> 26.358924 | S7: =AVERAGEIFS(Data!$O$2:$O$151,Data!$C$2:$C$151,$A7) -> 19.828516 | T7: =_xlfn.MAXIFS(Data!$P$2:$P$151,Data!$C$2:$C$151,$A7) -> 99.6 | U7: =AVERAGEIFS(Data!$AO$2:$AO$151,Data!$C$2:$C$151,$A7) -> 5.7217699 | V7: =AVERAGEIFS(Data!$AQ$2:$AQ$151,Data!$C$2:$C$151,$A7) -> 54.403523 | W7: =AVERAGEIFS(Data!$AR$2:$AR$151,Data!$C$2:$C$151,$A7) -> 0.054403523 | X7: =AVERAGEIFS(Data!$AS$2:$AS$151,Data!$C$2:$C$151,$A7) -> 73.316339 | Y7: =AVERAGEIFS(Data!$AV$2:$AV$151,Data!$C$2:$C$151,$A7) -> 1.5537635
A8: 50 | B8: =AVERAGEIFS(Data!$H$2:$H$151,Data!$C$2:$C$151,$A8) -> 1650.8788 | C8: =AVERAGEIFS(Data!$F$2:$F$151,Data!$C$2:$C$151,$A8) -> 222.65491 | D8: =AVERAGEIFS(Data!$G$2:$G$151,Data!$C$2:$C$151,$A8) -> 48.398874 | E8: =AVERAGEIFS(Data!$E$2:$E$151,Data!$C$2:$C$151,$A8) -> 229.6 | F8: =AVERAGEIFS(Data!$AG$2:$AG$151,Data!$C$2:$C$151,$A8) -> 227.6 | G8: =AVERAGEIFS(Data!$I$2:$I$151,Data!$C$2:$C$151,$A8) -> 86.993333 | H8: =AVERAGEIFS(Data!$K$2:$K$151,Data!$C$2:$C$151,$A8) -> 253.09 | I8: =AVERAGEIFS(Data!$Q$2:$Q$151,Data!$C$2:$C$151,$A8) -> 0.87573766 | J8: =AVERAGEIFS(Data!$S$2:$S$151,Data!$C$2:$C$151,$A8) -> 0.36735981 | K8: =AVERAGEIFS(Data!$U$2:$U$151,Data!$C$2:$C$151,$A8) -> 0.028203925 | L8: =AVERAGEIFS(Data!$W$2:$W$151,Data!$C$2:$C$151,$A8) -> 0.11796701 | M8: =_xlfn.MAXIFS(Data!$X$2:$X$151,Data!$C$2:$C$151,$A8) -> 0.239 | N8: =AVERAGEIFS(Data!$Y$2:$Y$151,Data!$C$2:$C$151,$A8) -> 0.37236658 | O8: =AVERAGEIFS(Data!$AI$2:$AI$151,Data!$C$2:$C$151,$A8) -> 8.9912974 | P8: =_xlfn.MAXIFS(Data!$AJ$2:$AJ$151,Data!$C$2:$C$151,$A8) -> 31.174143 | Q8: =AVERAGEIFS(Data!$AK$2:$AK$151,Data!$C$2:$C$151,$A8) -> 7.8902885 | R8: =_xlfn.MAXIFS(Data!$AL$2:$AL$151,Data!$C$2:$C$151,$A8) -> 27.279864 | S8: =AVERAGEIFS(Data!$O$2:$O$151,Data!$C$2:$C$151,$A8) -> 20.250199 | T8: =_xlfn.MAXIFS(Data!$P$2:$P$151,Data!$C$2:$C$151,$A8) -> 99.8 | U8: =AVERAGEIFS(Data!$AO$2:$AO$151,Data!$C$2:$C$151,$A8) -> 5.4639581 | V8: =AVERAGEIFS(Data!$AQ$2:$AQ$151,Data!$C$2:$C$151,$A8) -> 57.780759 | W8: =AVERAGEIFS(Data!$AR$2:$AR$151,Data!$C$2:$C$151,$A8) -> 0.057780759 | X8: =AVERAGEIFS(Data!$AS$2:$AS$151,Data!$C$2:$C$151,$A8) -> 78.325343 | Y8: =AVERAGEIFS(Data!$AV$2:$AV$151,Data!$C$2:$C$151,$A8) -> 1.6892502
A9: 100 | B9: =AVERAGEIFS(Data!$H$2:$H$151,Data!$C$2:$C$151,$A9) -> 1690.6106 | C9: =AVERAGEIFS(Data!$F$2:$F$151,Data!$C$2:$C$151,$A9) -> 278.4679 | D9: =AVERAGEIFS(Data!$G$2:$G$151,Data!$C$2:$C$151,$A9) -> 48.536134 | E9: =AVERAGEIFS(Data!$E$2:$E$151,Data!$C$2:$C$151,$A9) -> 231.5 | F9: =AVERAGEIFS(Data!$AG$2:$AG$151,Data!$C$2:$C$151,$A9) -> 230.5 | G9: =AVERAGEIFS(Data!$I$2:$I$151,Data!$C$2:$C$151,$A9) -> 86.153333 | H9: =AVERAGEIFS(Data!$K$2:$K$151,Data!$C$2:$C$151,$A9) -> 249.93667 | I9: =AVERAGEIFS(Data!$Q$2:$Q$151,Data!$C$2:$C$151,$A9) -> 0.86761716 | J9: =AVERAGEIFS(Data!$S$2:$S$151,Data!$C$2:$C$151,$A9) -> 0.36066146 | K9: =AVERAGEIFS(Data!$U$2:$U$151,Data!$C$2:$C$151,$A9) -> 0.027678808 | L9: =AVERAGEIFS(Data!$W$2:$W$151,Data!$C$2:$C$151,$A9) -> 0.11656529 | M9: =_xlfn.MAXIFS(Data!$X$2:$X$151,Data!$C$2:$C$151,$A9) -> 0.244 | N9: =AVERAGEIFS(Data!$Y$2:$Y$151,Data!$C$2:$C$151,$A9) -> 0.36738447 | O9: =AVERAGEIFS(Data!$AI$2:$AI$151,Data!$C$2:$C$151,$A9) -> 8.9885251 | P9: =_xlfn.MAXIFS(Data!$AJ$2:$AJ$151,Data!$C$2:$C$151,$A9) -> 31.122929 | Q9: =AVERAGEIFS(Data!$AK$2:$AK$151,Data!$C$2:$C$151,$A9) -> 7.8838152 | R9: =_xlfn.MAXIFS(Data!$AL$2:$AL$151,Data!$C$2:$C$151,$A9) -> 27.234709 | S9: =AVERAGEIFS(Data!$O$2:$O$151,Data!$C$2:$C$151,$A9) -> 20.282941 | T9: =_xlfn.MAXIFS(Data!$P$2:$P$151,Data!$C$2:$C$151,$A9) -> 99.6 | U9: =AVERAGEIFS(Data!$AO$2:$AO$151,Data!$C$2:$C$151,$A9) -> 5.3566186 | V9: =AVERAGEIFS(Data!$AQ$2:$AQ$151,Data!$C$2:$C$151,$A9) -> 59.17137 | W9: =AVERAGEIFS(Data!$AR$2:$AR$151,Data!$C$2:$C$151,$A9) -> 0.05917137 | X9: =AVERAGEIFS(Data!$AS$2:$AS$151,Data!$C$2:$C$151,$A9) -> 80.224357 | Y9: =AVERAGEIFS(Data!$AV$2:$AV$151,Data!$C$2:$C$151,$A9) -> 1.769894

Sheet Rate_Effect
A1: Request-rate effect: full grids behind Section 3 of the report
A2: Each cell averages the load points that share the row and column values (for the output-length grids, the mean of the five input lengths). Every cell is a formula over the Data sheet.
A4: Mean time to first token (ms), by output length and request rate
A5: Output length | B5: 5 | C5: 10 | D5: 20 | E5: 50 | F5: 100
A6: 128 | B6: =AVERAGEIFS(Data!$F$2:$F$151,Data!$B$2:$B$151,$A6,Data!$C$2:$C$151,B$5) -> 133.28094 | C6: =AVERAGEIFS(Data!$F$2:$F$151,Data!$B$2:$B$151,$A6,Data!$C$2:$C$151,C$5) -> 89.51893 | D6: =AVERAGEIFS(Data!$F$2:$F$151,Data!$B$2:$B$151,$A6,Data!$C$2:$C$151,D$5) -> 97.412873 | E6: =AVERAGEIFS(Data!$F$2:$F$151,Data!$B$2:$B$151,$A6,Data!$C$2:$C$151,E$5) -> 103.64719 | F6: =AVERAGEIFS(Data!$F$2:$F$151,Data!$B$2:$B$151,$A6,Data!$C$2:$C$151,F$5) -> 107.86667
A7: 512 | B7: =AVERAGEIFS(Data!$F$2:$F$151,Data!$B$2:$B$151,$A7,Data!$C$2:$C$151,B$5) -> 96.064982 | C7: =AVERAGEIFS(Data!$F$2:$F$151,Data!$B$2:$B$151,$A7,Data!$C$2:$C$151,C$5) -> 96.869903 | D7: =AVERAGEIFS(Data!$F$2:$F$151,Data!$B$2:$B$151,$A7,Data!$C$2:$C$151,D$5) -> 98.129096 | E7: =AVERAGEIFS(Data!$F$2:$F$151,Data!$B$2:$B$151,$A7,Data!$C$2:$C$151,E$5) -> 103.37167 | F7: =AVERAGEIFS(Data!$F$2:$F$151,Data!$B$2:$B$151,$A7,Data!$C$2:$C$151,F$5) -> 108.6542
A8: 1024 | B8: =AVERAGEIFS(Data!$F$2:$F$151,Data!$B$2:$B$151,$A8,Data!$C$2:$C$151,B$5) -> 96.595076 | C8: =AVERAGEIFS(Data!$F$2:$F$151,Data!$B$2:$B$151,$A8,Data!$C$2:$C$151,C$5) -> 95.797372 | D8: =AVERAGEIFS(Data!$F$2:$F$151,Data!$B$2:$B$151,$A8,Data!$C$2:$C$151,D$5) -> 98.299635 | E8: =AVERAGEIFS(Data!$F$2:$F$151,Data!$B$2:$B$151,$A8,Data!$C$2:$C$151,E$5) -> 102.95427 | F8: =AVERAGEIFS(Data!$F$2:$F$151,Data!$B$2:$B$151,$A8,Data!$C$2:$C$151,F$5) -> 108.78853
A9: 2048 | B9: =AVERAGEIFS(Data!$F$2:$F$151,Data!$B$2:$B$151,$A9,Data!$C$2:$C$151,B$5) -> 156.60164 | C9: =AVERAGEIFS(Data!$F$2:$F$151,Data!$B$2:$B$151,$A9,Data!$C$2:$C$151,C$5) -> 95.741483 | D9: =AVERAGEIFS(Data!$F$2:$F$151,Data!$B$2:$B$151,$A9,Data!$C$2:$C$151,D$5) -> 97.342898 | E9: =AVERAGEIFS(Data!$F$2:$F$151,Data!$B$2:$B$151,$A9,Data!$C$2:$C$151,E$5) -> 103.14227 | F9: =AVERAGEIFS(Data!$F$2:$F$151,Data!$B$2:$B$151,$A9,Data!$C$2:$C$151,F$5) -> 108.30461
A10: 5120 | B10: =AVERAGEIFS(Data!$F$2:$F$151,Data!$B$2:$B$151,$A10,Data!$C$2:$C$151,B$5) -> 94.635946 | C10: =AVERAGEIFS(Data!$F$2:$F$151,Data!$B$2:$B$151,$A10,Data!$C$2:$C$151,C$5) -> 95.36703 | D10: =AVERAGEIFS(Data!$F$2:$F$151,Data!$B$2:$B$151,$A10,Data!$C$2:$C$151,D$5) -> 96.232356 | E10: =AVERAGEIFS(Data!$F$2:$F$151,Data!$B$2:$B$151,$A10,Data!$C$2:$C$151,E$5) -> 101.77993 | F10: =AVERAGEIFS(Data!$F$2:$F$151,Data!$B$2:$B$151,$A10,Data!$C$2:$C$151,F$5) -> 107.27805
A11: 10240 | B11: =AVERAGEIFS(Data!$F$2:$F$151,Data!$B$2:$B$151,$A11,Data!$C$2:$C$151,B$5) -> 196.90449 | C11: =AVERAGEIFS(Data!$F$2:$F$151,Data!$B$2:$B$151,$A11,Data!$C$2:$C$151,C$5) -> 178.26573 | D11: =AVERAGEIFS(Data!$F$2:$F$151,Data!$B$2:$B$151,$A11,Data!$C$2:$C$151,D$5) -> 337.91058 | E11: =AVERAGEIFS(Data!$F$2:$F$151,Data!$B$2:$B$151,$A11,Data!$C$2:$C$151,E$5) -> 821.03415 | F11: =AVERAGEIFS(Data!$F$2:$F$151,Data!$B$2:$B$151,$A11,Data!$C$2:$C$151,F$5) -> 1129.9154
A13: Mean time to first token (ms), 10,240-token outputs only, by input length and request rate
A14: Input length | B14: 5 | C14: 10 | D14: 20 | E14: 50 | F14: 100
A15: 128 | B15: =AVERAGEIFS(Data!$F$2:$F$151,Data!$A$2:$A$151,$A15,Data!$C$2:$C$151,B$14,Data!$B$2:$B$151,10240) -> 120.8392 | C15: =AVERAGEIFS(Data!$F$2:$F$151,Data!$A$2:$A$151,$A15,Data!$C$2:$C$151,C$14,Data!$B$2:$B$151,10240) -> 100.54687 | D15: =AVERAGEIFS(Data!$F$2:$F$151,Data!$A$2:$A$151,$A15,Data!$C$2:$C$151,D$14,Data!$B$2:$B$151,10240) -> 106.26711 | E15: =AVERAGEIFS(Data!$F$2:$F$151,Data!$A$2:$A$151,$A15,Data!$C$2:$C$151,E$14,Data!$B$2:$B$151,10240) -> 125.62037 | F15: =AVERAGEIFS(Data!$F$2:$F$151,Data!$A$2:$A$151,$A15,Data!$C$2:$C$151,F$14,Data!$B$2:$B$151,10240) -> 171.65484
A16: 256 | B16: =AVERAGEIFS(Data!$F$2:$F$151,Data!$A$2:$A$151,$A16,Data!$C$2:$C$151,B$14,Data!$B$2:$B$151,10240) -> 131.38473 | C16: =AVERAGEIFS(Data!$F$2:$F$151,Data!$A$2:$A$151,$A16,Data!$C$2:$C$151,C$14,Data!$B$2:$B$151,10240) -> 114.50622 | D16: =AVERAGEIFS(Data!$F$2:$F$151,Data!$A$2:$A$151,$A16,Data!$C$2:$C$151,D$14,Data!$B$2:$B$151,10240) -> 129.56262 | E16: =AVERAGEIFS(Data!$F$2:$F$151,Data!$A$2:$A$151,$A16,Data!$C$2:$C$151,E$14,Data!$B$2:$B$151,10240) -> 201.1112 | F16: =AVERAGEIFS(Data!$F$2:$F$151,Data!$A$2:$A$151,$A16,Data!$C$2:$C$151,F$14,Data!$B$2:$B$151,10240) -> 462.22994
A17: 384 | B17: =AVERAGEIFS(Data!$F$2:$F$151,Data!$A$2:$A$151,$A17,Data!$C$2:$C$151,B$14,Data!$B$2:$B$151,10240) -> 145.1889 | C17: =AVERAGEIFS(Data!$F$2:$F$151,Data!$A$2:$A$151,$A17,Data!$C$2:$C$151,C$14,Data!$B$2:$B$151,10240) -> 135.81356 | D17: =AVERAGEIFS(Data!$F$2:$F$151,Data!$A$2:$A$151,$A17,Data!$C$2:$C$151,D$14,Data!$B$2:$B$151,10240) -> 168.13141 | E17: =AVERAGEIFS(Data!$F$2:$F$151,Data!$A$2:$A$151,$A17,Data!$C$2:$C$151,E$14,Data!$B$2:$B$151,10240) -> 415.36238 | F17: =AVERAGEIFS(Data!$F$2:$F$151,Data!$A$2:$A$151,$A17,Data!$C$2:$C$151,F$14,Data!$B$2:$B$151,10240) -> 851.51104
A18: 512 | B18: =AVERAGEIFS(Data!$F$2:$F$151,Data!$A$2:$A$151,$A18,Data!$C$2:$C$151,B$14,Data!$B$2:$B$151,10240) -> 166.28861 | C18: =AVERAGEIFS(Data!$F$2:$F$151,Data!$A$2:$A$151,$A18,Data!$C$2:$C$151,C$14,Data!$B$2:$B$151,10240) -> 167.55968 | D18: =AVERAGEIFS(Data!$F$2:$F$151,Data!$A$2:$A$151,$A18,Data!$C$2:$C$151,D$14,Data!$B$2:$B$151,10240) -> 235.02067 | E18: =AVERAGEIFS(Data!$F$2:$F$151,Data!$A$2:$A$151,$A18,Data!$C$2:$C$151,E$14,Data!$B$2:$B$151,10240) -> 876.44848 | F18: =AVERAGEIFS(Data!$F$2:$F$151,Data!$A$2:$A$151,$A18,Data!$C$2:$C$151,F$14,Data!$B$2:$B$151,10240) -> 1205.2986
A19: 1024 | B19: =AVERAGEIFS(Data!$F$2:$F$151,Data!$A$2:$A$151,$A19,Data!$C$2:$C$151,B$14,Data!$B$2:$B$151,10240) -> 420.82099 | C19: =AVERAGEIFS(Data!$F$2:$F$151,Data!$A$2:$A$151,$A19,Data!$C$2:$C$151,C$14,Data!$B$2:$B$151,10240) -> 372.90233 | D19: =AVERAGEIFS(Data!$F$2:$F$151,Data!$A$2:$A$151,$A19,Data!$C$2:$C$151,D$14,Data!$B$2:$B$151,10240) -> 1050.5711 | E19: =AVERAGEIFS(Data!$F$2:$F$151,Data!$A$2:$A$151,$A19,Data!$C$2:$C$151,E$14,Data!$B$2:$B$151,10240) -> 2486.6283 | F19: =AVERAGEIFS(Data!$F$2:$F$151,Data!$A$2:$A$151,$A19,Data!$C$2:$C$151,F$14,Data!$B$2:$B$151,10240) -> 2958.8823
A21: Tokens per joule (4-GPU average power), by output length and request rate
A22: Output length | B22: 5 | C22: 10 | D22: 20 | E22: 50 | F22: 100
A23: 128 | B23: =AVERAGEIFS(Data!$AV$2:$AV$151,Data!$B$2:$B$151,$A23,Data!$C$2:$C$151,B$22) -> 0.58219511 | C23: =AVERAGEIFS(Data!$AV$2:$AV$151,Data!$B$2:$B$151,$A23,Data!$C$2:$C$151,C$22) -> 1.0856125 | D23: =AVERAGEIFS(Data!$AV$2:$AV$151,Data!$B$2:$B$151,$A23,Data!$C$2:$C$151,D$22) -> 1.6048553 | E23: =AVERAGEIFS(Data!$AV$2:$AV$151,Data!$B$2:$B$151,$A23,Data!$C$2:$C$151,E$22) -> 2.234791 | F23: =AVERAGEIFS(Data!$AV$2:$AV$151,Data!$B$2:$B$151,$A23,Data!$C$2:$C$151,F$22) -> 2.5718708
A24: 512 | B24: =AVERAGEIFS(Data!$AV$2:$AV$151,Data!$B$2:$B$151,$A24,Data!$C$2:$C$151,B$22) -> 1.2689759 | C24: =AVERAGEIFS(Data!$AV$2:$AV$151,Data!$B$2:$B$151,$A24,Data!$C$2:$C$151,C$22) -> 1.5763974 | D24: =AVERAGEIFS(Data!$AV$2:$AV$151,Data!$B$2:$B$151,$A24,Data!$C$2:$C$151,D$22) -> 1.7816554 | E24: =AVERAGEIFS(Data!$AV$2:$AV$151,Data!$B$2:$B$151,$A24,Data!$C$2:$C$151,E$22) -> 1.9294092 | F24: =AVERAGEIFS(Data!$AV$2:$AV$151,Data!$B$2:$B$151,$A24,Data!$C$2:$C$151,F$22) -> 1.9969295
